Workbook

Sheet Final Report
E1: ANALYSIS
A2: Order ID | B2: AWB Number | C2: Total Weight | D2: Total weight X (KG) | E2: Weight slab (KG) | F2: Total weight as per Courier Company (KG | G2: Weight slab charged by Courier Company (KG) | H2: Delivery Zone | I2: Delivery Zone charged | J2: Type of Shipment | K2: Fixed charges | L2: Additional charges | M2: Expected Charge | N2: Charges Billed | O2: Difference Between Expected Charges and Billed Charges (Rs.)
A3: 2001806210 | B3: =_xlfn.XLOOKUP('Final Report'!A3,Invoice!B:B,Invoice!A:A) -> 1091117221940 | C3: 220 | D3: =C3/1000 -> 0.22 | E3: =CEILING(D3,0.5) -> 0.5 | F3: =_xlfn.XLOOKUP('Final Report'!A3,Invoice!B:B,Invoice!C:C) -> 2.92 | G3: =_xlfn.CEILING.MATH(F3,0.5) -> 3 | H3: =_xlfn.XLOOKUP('Final Report'!A3,Invoice!B:B,Invoice!F:F) -> b | I3: =_xlfn.XLOOKUP('Final Report'!A3,Invoice!B:B,Invoice!F:F) -> b | J3: =_xlfn.XLOOKUP(I3,Invoice!F:F,Invoice!G:G) -> Forward charges | K3: =IF(J3="Forward charges", IF(I3="a",29.5, IF(I3="b",33, IF(I3="c",40.1, IF(I3="d",45.4, IF(I3="e",56.6,0))))), IF(I3="a",13.6, IF(I3="b",20.5, IF(I3="c",31.9, IF(I3="d",41.3, IF(I3="e",50.7,0)))))) -> 33 | L3: =IF(J3="Forward charges", IF(I3="a",23.6, IF(I3="b",28.3, IF(I3="c",38.9, IF(I3="d",44.8, IF(I3="e",55.5,0))))), IF(I3="a",23.6, IF(I3="b",28.3, IF(I3="c",38.9, IF(I3="d",44.8, IF(I3="e",55.5,0)))))) -> 28.3 | M3: =K3 + ((E3*2 - 1) * L3) -> 33 | N3: =_xlfn.XLOOKUP('Final Report'!A3,Invoice!B:B,Invoice!H:H) -> 174.5 | O3: =N3-M3 -> 141.5
A4: 2001806226 | B4: =_xlfn.XLOOKUP('Final Report'!A4,Invoice!B:B,Invoice!A:A) -> 1091117222065 | C4: 480 | D4: =C4/1000 -> 0.48 | E4: =CEILING(D4,0.5) -> 0.5 | F4: =_xlfn.XLOOKUP('Final Report'!A4,Invoice!B:B,Invoice!C:C) -> 0.68 | G4: =_xlfn.CEILING.MATH(F4,0.5) -> 1 | H4: =_xlfn.XLOOKUP('Final Report'!A4,Invoice!B:B,Invoice!F:F) -> d | I4: =_xlfn.XLOOKUP('Final Report'!A4,Invoice!B:B,Invoice!F:F) -> d | J4: =_xlfn.XLOOKUP(I4,Invoice!F:F,Invoice!G:G) -> Forward charges | K4: =IF(J4="Forward charges", IF(I4="a",29.5, IF(I4="b",33, IF(I4="c",40.1, IF(I4="d",45.4, IF(I4="e",56.6,0))))), IF(I4="a",13.6, IF(I4="b",20.5, IF(I4="c",31.9, IF(I4="d",41.3, IF(I4="e",50.7,0)))))) -> 45.4 | L4: =IF(J4="Forward charges", IF(I4="a",23.6, IF(I4="b",28.3, IF(I4="c",38.9, IF(I4="d",44.8, IF(I4="e",55.5,0))))), IF(I4="a",23.6, IF(I4="b",28.3, IF(I4="c",38.9, IF(I4="d",44.8, IF(I4="e",55.5,0)))))) -> 44.8 | M4: =K4 + ((E4*2 - 1) * L4) -> 45.4 | N4: =_xlfn.XLOOKUP('Final Report'!A4,Invoice!B:B,Invoice!H:H) -> 90.2 | O4: =N4-M4 -> 44.8
A5: 2001806229 | B5: =_xlfn.XLOOKUP('Final Report'!A5,Invoice!B:B,Invoice!A:A) -> 1091117222080 | C5: 500 | D5: =C5/1000 -> 0.5 | E5: =CEILING(D5,0.5) -> 0.5 | F5: =_xlfn.XLOOKUP('Final Report'!A5,Invoice!B:B,Invoice!C:C) -> 0.71 | G5: =_xlfn.CEILING.MATH(F5,0.5) -> 1 | H5: =_xlfn.XLOOKUP('Final Report'!A5,Invoice!B:B,Invoice!F:F) -> d | I5: =_xlfn.XLOOKUP('Final Report'!A5,Invoice!B:B,Invoice!F:F) -> d | J5: =_xlfn.XLOOKUP(I5,Invoice!F:F,Invoice!G:G) -> Forward charges | K5: =IF(J5="Forward charges", IF(I5="a",29.5, IF(I5="b",33, IF(I5="c",40.1, IF(I5="d",45.4, IF(I5="e",56.6,0))))), IF(I5="a",13.6, IF(I5="b",20.5, IF(I5="c",31.9, IF(I5="d",41.3, IF(I5="e",50.7,0)))))) -> 45.4 | L5: =IF(J5="Forward charges", IF(I5="a",23.6, IF(I5="b",28.3, IF(I5="c",38.9, IF(I5="d",44.8, IF(I5="e",55.5,0))))), IF(I5="a",23.6, IF(I5="b",28.3, IF(I5="c",38.9, IF(I5="d",44.8, IF(I5="e",55.5,0)))))) -> 44.8 | M5: =K5 + ((E5*2 - 1) * L5) -> 45.4 | N5: =_xlfn.XLOOKUP('Final Report'!A5,Invoice!B:B,Invoice!H:H) -> 90.2 | O5: =N5-M5 -> 44.8
A6: 2001806232 | B6: =_xlfn.XLOOKUP('Final Report'!A6,Invoice!B:B,Invoice!A:A) -> 1091117222124 | C6: 1302 | D6: =C6/1000 -> 1.302 | E6: =CEILING(D6,0.5) -> 1.5 | F6: =_xlfn.XLOOKUP('Final Report'!A6,Invoice!B:B,Invoice!C:C) -> 1.3 | G6: =_xlfn.CEILING.MATH(F6,0.5) -> 1.5 | H6: =_xlfn.XLOOKUP('Final Report'!A6,Invoice!B:B,Invoice!F:F) -> d | I6: =_xlfn.XLOOKUP('Final Report'!A6,Invoice!B:B,Invoice!F:F) -> d | J6: =_xlfn.XLOOKUP(I6,Invoice!F:F,Invoice!G:G) -> Forward charges | K6: =IF(J6="Forward charges", IF(I6="a",29.5, IF(I6="b",33, IF(I6="c",40.1, IF(I6="d",45.4, IF(I6="e",56.6,0))))), IF(I6="a",13.6, IF(I6="b",20.5, IF(I6="c",31.9, IF(I6="d",41.3, IF(I6="e",50.7,0)))))) -> 45.4 | L6: =IF(J6="Forward charges", IF(I6="a",23.6, IF(I6="b",28.3, IF(I6="c",38.9, IF(I6="d",44.8, IF(I6="e",55.5,0))))), IF(I6="a",23.6, IF(I6="b",28.3, IF(I6="c",38.9, IF(I6="d",44.8, IF(I6="e",55.5,0)))))) -> 44.8 | M6: =K6 + ((E6*2 - 1) * L6) -> 135 | N6: =_xlfn.XLOOKUP('Final Report'!A6,Invoice!B:B,Invoice!H:H) -> 135 | O6: =N6-M6 -> 0
A7: 2001806233 | B7: =_xlfn.XLOOKUP('Final Report'!A7,Invoice!B:B,Invoice!A:A) -> 1091117222135 | C7: 245 | D7: =C7/1000 -> 0.245 | E7: =CEILING(D7,0.5) -> 0.5 | F7: =_xlfn.XLOOKUP('Final Report'!A7,Invoice!B:B,Invoice!C:C) -> 0.78 | G7: =_xlfn.CEILING.MATH(F7,0.5) -> 1 | H7: =_xlfn.XLOOKUP('Final Report'!A7,Invoice!B:B,Invoice!F:F) -> b | I7: =_xlfn.XLOOKUP('Final Report'!A7,Invoice!B:B,Invoice!F:F) -> b | J7: =_xlfn.XLOOKUP(I7,Invoice!F:F,Invoice!G:G) -> Forward charges | K7: =IF(J7="Forward charges", IF(I7="a",29.5, IF(I7="b",33, IF(I7="c",40.1, IF(I7="d",45.4, IF(I7="e",56.6,0))))), IF(I7="a",13.6, IF(I7="b",20.5, IF(I7="c",31.9, IF(I7="d",41.3, IF(I7="e",50.7,0)))))) -> 33 | L7: =IF(J7="Forward charges", IF(I7="a",23.6, IF(I7="b",28.3, IF(I7="c",38.9, IF(I7="d",44.8, IF(I7="e",55.5,0))))), IF(I7="a",23.6, IF(I7="b",28.3, IF(I7="c",38.9, IF(I7="d",44.8, IF(I7="e",55.5,0)))))) -> 28.3 | M7: =K7 + ((E7*2 - 1) * L7) -> 33 | N7: =_xlfn.XLOOKUP('Final Report'!A7,Invoice!B:B,Invoice!H:H) -> 61.3 | O7: =N7-M7 -> 28.3
A8: 2001806251 | B8: =_xlfn.XLOOKUP('Final Report'!A8,Invoice!B:B,Invoice!A:A) -> 1091117222146 | C8: 245 | D8: =C8/1000 -> 0.245 | E8: =CEILING(D8,0.5) -> 0.5 | F8: =_xlfn.XLOOKUP('Final Report'!A8,Invoice!B:B,Invoice!C:C) -> 1.27 | G8: =_xlfn.CEILING.MATH(F8,0.5) -> 1.5 | H8: =_xlfn.XLOOKUP('Final Report'!A8,Invoice!B:B,Invoice!F:F) -> d | I8: =_xlfn.XLOOKUP('Final Report'!A8,Invoice!B:B,Invoice!F:F) -> d | J8: =_xlfn.XLOOKUP(I8,Invoice!F:F,Invoice!G:G) -> Forward charges | K8: =IF(J8="Forward charges", IF(I8="a",29.5, IF(I8="b",33, IF(I8="c",40.1, IF(I8="d",45.4, IF(I8="e",56.6,0))))), IF(I8="a",13.6, IF(I8="b",20.5, IF(I8="c",31.9, IF(I8="d",41.3, IF(I8="e",50.7,0)))))) -> 45.4 | L8: =IF(J8="Forward charges", IF(I8="a",23.6, IF(I8="b",28.3, IF(I8="c",38.9, IF(I8="d",44.8, IF(I8="e",55.5,0))))), IF(I8="a",23.6, IF(I8="b",28.3, IF(I8="c",38.9, IF(I8="d",44.8, IF(I8="e",55.5,0)))))) -> 44.8 | M8: =K8 + ((E8*2 - 1) * L8) -> 45.4 | N8: =_xlfn.XLOOKUP('Final Report'!A8,Invoice!B:B,Invoice!H:H) -> 135 | O8: =N8-M8 -> 89.6
A9: 2001806273 | B9: =_xlfn.XLOOKUP('Final Report'!A9,Invoice!B:B,Invoice!A:A) -> 1091117222194 | C9: 615 | D9: =C9/1000 -> 0.615 | E9: =CEILING(D9,0.5) -> 1 | F9: =_xlfn.XLOOKUP('Final Report'!A9,Invoice!B:B,Invoice!C:C) -> 1 | G9: =_xlfn.CEILING.MATH(F9,0.5) -> 1 | H9: =_xlfn.XLOOKUP('Final Report'!A9,Invoice!B:B,Invoice!F:F) -> d | I9: =_xlfn.XLOOKUP('Final Report'!A9,Invoice!B:B,Invoice!F:F) -> d | J9: =_xlfn.XLOOKUP(I9,Invoice!F:F,Invoice!G:G) -> Forward charges | K9: =IF(J9="Forward charges", IF(I9="a",29.5, IF(I9="b",33, IF(I9="c",40.1, IF(I9="d",45.4, IF(I9="e",56.6,0))))), IF(I9="a",13.6, IF(I9="b",20.5, IF(I9="c",31.9, IF(I9="d",41.3, IF(I9="e",50.7,0)))))) -> 45.4 | L9: =IF(J9="Forward charges", IF(I9="a",23.6, IF(I9="b",28.3, IF(I9="c",38.9, IF(I9="d",44.8, IF(I9="e",55.5,0))))), IF(I9="a",23.6, IF(I9="b",28.3, IF(I9="c",38.9, IF(I9="d",44.8, IF(I9="e",55.5,0)))))) -> 44.8 | M9: =K9 + ((E9*2 - 1) * L9) -> 90.2 | N9: =_xlfn.XLOOKUP('Final Report'!A9,Invoice!B:B,Invoice!H:H) -> 90.2 | O9: =N9-M9 -> 0
A10: 2001806304 | B10: =_xlfn.XLOOKUP('Final Report'!A10,Invoice!B:B,Invoice!A:A) -> 1091117222360 | C10: 500 | D10: =C10/1000 -> 0.5 | E10: =CEILING(D10,0.5) -> 0.5 | F10: =_xlfn.XLOOKUP('Final Report'!A10,Invoice!B:B,Invoice!C:C) -> 0.71 | G10: =_xlfn.CEILING.MATH(F10,0.5) -> 1 | H10: =_xlfn.XLOOKUP('Final Report'!A10,Invoice!B:B,Invoice!F:F) -> d | I10: =_xlfn.XLOOKUP('Final Report'!A10,Invoice!B:B,Invoice!F:F) -> d | J10: =_xlfn.XLOOKUP(I10,Invoice!F:F,Invoice!G:G) -> Forward charges | K10: =IF(J10="Forward charges", IF(I10="a",29.5, IF(I10="b",33, IF(I10="c",40.1, IF(I10="d",45.4, IF(I10="e",56.6,0))))), IF(I10="a",13.6, IF(I10="b",20.5, IF(I10="c",31.9, IF(I10="d",41.3, IF(I10="e",50.7,0)))))) -> 45.4 | L10: =IF(J10="Forward charges", IF(I10="a",23.6, IF(I10="b",28.3, IF(I10="c",38.9, IF(I10="d",44.8, IF(I10="e",55.5,0))))), IF(I10="a",23.6, IF(I10="b",28.3, IF(I10="c",38.9, IF(I10="d",44.8, IF(I10="e",55.5,0)))))) -> 44.8 | M10: =K10 + ((E10*2 - 1) * L10) -> 45.4 | N10: =_xlfn.XLOOKUP('Final Report'!A10,Invoice!B:B,Invoice!H:H) -> 90.2 | O10: =N10-M10 -> 44.8
A11: 2001806338 | B11: =_xlfn.XLOOKUP('Final Report'!A11,Invoice!B:B,Invoice!A:A) -> 1091117222570 | C11: 500 | D11: =C11/1000 -> 0.5 | E11: =CEILING(D11,0.5) -> 0.5 | F11: =_xlfn.XLOOKUP('Final Report'!A11,Invoice!B:B,Invoice!C:C) -> 0.7 | G11: =_xlfn.CEILING.MATH(F11,0.5) -> 1 | H11: =_xlfn.XLOOKUP('Final Report'!A11,Invoice!B:B,Invoice!F:F) -> d | I11: =_xlfn.XLOOKUP('Final Report'!A11,Invoice!B:B,Invoice!F:F) -> d | J11: =_xlfn.XLOOKUP(I11,Invoice!F:F,Invoice!G:G) -> Forward charges | K11: =IF(J11="Forward charges", IF(I11="a",29.5, IF(I11="b",33, IF(I11="c",40.1, IF(I11="d",45.4, IF(I11="e",56.6,0))))), IF(I11="a",13.6, IF(I11="b",20.5, IF(I11="c",31.9, IF(I11="d",41.3, IF(I11="e",50.7,0)))))) -> 45.4 | L11: =IF(J11="Forward charges", IF(I11="a",23.6, IF(I11="b",28.3, IF(I11="c",38.9, IF(I11="d",44.8, IF(I11="e",55.5,0))))), IF(I11="a",23.6, IF(I11="b",28.3, IF(I11="c",38.9, IF(I11="d",44.8, IF(I11="e",55.5,0)))))) -> 44.8 | M11: =K11 + ((E11*2 - 1) * L11) -> 45.4 | N11: =_xlfn.XLOOKUP('Final Report'!A11,Invoice!B:B,Invoice!H:H) -> 90.2 | O11: =N11-M11 -> 44.8
A12: 2001806408 | B12: =_xlfn.XLOOKUP('Final Report'!A12,Invoice!B:B,Invoice!A:A) -> 1091117222931 | C12: 2265 | D12: =C12/1000 -> 2.265 | E12: =CEILING(D12,0.5) -> 2.5 | F12: =_xlfn.XLOOKUP('Final Report'!A12,Invoice!B:B,Invoice!C:C) -> 2.5 | G12: =_xlfn.CEILING.MATH(F12,0.5) -> 2.5 | H12: =_xlfn.XLOOKUP('Final Report'!A12,Invoice!B:B,Invoice!F:F) -> d | I12: =_xlfn.XLOOKUP('Final Report'!A12,Invoice!B:B,Invoice!F:F) -> d | J12: =_xlfn.XLOOKUP(I12,Invoice!F:F,Invoice!G:G) -> Forward charges | K12: =IF(J12="Forward charges", IF(I12="a",29.5, IF(I12="b",33, IF(I12="c",40.1, IF(I12="d",45.4, IF(I12="e",56.6,0))))), IF(I12="a",13.6, IF(I12="b",20.5, IF(I12="c",31.9, IF(I12="d",41.3, IF(I12="e",50.7,0)))))) -> 45.4 | L12: =IF(J12="Forward charges", IF(I12="a",23.6, IF(I12="b",28.3, IF(I12="c",38.9, IF(I12="d",44.8, IF(I12="e",55.5,0))))), IF(I12="a",23.6, IF(I12="b",28.3, IF(I12="c",38.9, IF(I12="d",44.8, IF(I12="e",55.5,0)))))) -> 44.8 | M12: =K12 + ((E12*2 - 1) * L12) -> 224.6 | N12: =_xlfn.XLOOKUP('Final Report'!A12,Invoice!B:B,Invoice!H:H) -> 224.6 | O12: =N12-M12 -> 0
A13: 2001806446 | B13: =_xlfn.XLOOKUP('Final Report'!A13,Invoice!B:B,Invoice!A:A) -> 1091117223211 | C13: 500 | D13: =C13/1000 -> 0.5 | E13: =CEILING(D13,0.5) -> 0.5 | F13: =_xlfn.XLOOKUP('Final Report'!A13,Invoice!B:B,Invoice!C:C) -> 0.69 | G13: =_xlfn.CEILING.MATH(F13,0.5) -> 1 | H13: =_xlfn.XLOOKUP('Final Report'!A13,Invoice!B:B,Invoice!F:F) -> d | I13: =_xlfn.XLOOKUP('Final Report'!A13,Invoice!B:B,Invoice!F:F) -> d | J13: =_xlfn.XLOOKUP(I13,Invoice!F:F,Invoice!G:G) -> Forward charges | K13: =IF(J13="Forward charges", IF(I13="a",29.5, IF(I13="b",33, IF(I13="c",40.1, IF(I13="d",45.4, IF(I13="e",56.6,0))))), IF(I13="a",13.6, IF(I13="b",20.5, IF(I13="c",31.9, IF(I13="d",41.3, IF(I13="e",50.7,0)))))) -> 45.4 | L13: =IF(J13="Forward charges", IF(I13="a",23.6, IF(I13="b",28.3, IF(I13="c",38.9, IF(I13="d",44.8, IF(I13="e",55.5,0))))), IF(I13="a",23.6, IF(I13="b",28.3, IF(I13="c",38.9, IF(I13="d",44.8, IF(I13="e",55.5,0)))))) -> 44.8 | M13: =K13 + ((E13*2 - 1) * L13) -> 45.4 | N13: =_xlfn.XLOOKUP('Final Report'!A13,Invoice!B:B,Invoice!H:H) -> 90.2 | O13: =N13-M13 -> 44.8
A14: 2001806458 | B14: =_xlfn.XLOOKUP('Final Report'!A14,Invoice!B:B,Invoice!A:A) -> 1091117223244 | C14: 700 | D14: =C14/1000 -> 0.7 | E14: =CEILING(D14,0.5) -> 1 | F14: =_xlfn.XLOOKUP('Final Report'!A14,Invoice!B:B,Invoice!C:C) -> 1 | G14: =_xlfn.CEILING.MATH(F14,0.5) -> 1 | H14: =_xlfn.XLOOKUP('Final Report'!A14,Invoice!B:B,Invoice!F:F) -> b | I14: =_xlfn.XLOOKUP('Final Report'!A14,Invoice!B:B,Invoice!F:F) -> b | J14: =_xlfn.XLOOKUP(I14,Invoice!F:F,Invoice!G:G) -> Forward charges | K14: =IF(J14="Forward charges", IF(I14="a",29.5, IF(I14="b",33, IF(I14="c",40.1, IF(I14="d",45.4, IF(I14="e",56.6,0))))), IF(I14="a",13.6, IF(I14="b",20.5, IF(I14="c",31.9, IF(I14="d",41.3, IF(I14="e",50.7,0)))))) -> 33 | L14: =IF(J14="Forward charges", IF(I14="a",23.6, IF(I14="b",28.3, IF(I14="c",38.9, IF(I14="d",44.8, IF(I14="e",55.5,0))))), IF(I14="a",23.6, IF(I14="b",28.3, IF(I14="c",38.9, IF(I14="d",44.8, IF(I14="e",55.5,0)))))) -> 28.3 | M14: =K14 + ((E14*2 - 1) * L14) -> 61.3 | N14: =_xlfn.XLOOKUP('Final Report'!A14,Invoice!B:B,Invoice!H:H) -> 61.3 | O14: =N14-M14 -> 0
... A126: 2001827036 | B126: =_xlfn.XLOOKUP('Final Report'!A126,Invoice!B:B,Invoice!A:A) -> 1091122418320 | C126: 1676 | D126: =C126/1000 -> 1.676 | E126: =CEILING(D126,0.5) -> 2 | F126: =_xlfn.XLOOKUP('Final Report'!A126,Invoice!B:B,Invoice!C:C) -> 1.6 | G126: =_xlfn.CEILING.MATH(F126,0.5) -> 2 | H126: =_xlfn.XLOOKUP('Final Report'!A126,Invoice!B:B,Invoice!F:F) -> b | I126: =_xlfn.XLOOKUP('Final Report'!A126,Invoice!B:B,Invoice!F:F) -> b | J126: =_xlfn.XLOOKUP(I126,Invoice!F:F,Invoice!G:G) -> Forward charges | K126: =IF(J126="Forward charges", IF(I126="a",29.5, IF(I126="b",33, IF(I126="c",40.1, IF(I126="d",45.4, IF(I126="e",56.6,0))))), IF(I126="a",13.6, IF(I126="b",20.5, IF(I126="c",31.9, IF(I126="d",41.3, IF(I126="e",50.7,0)))))) -> 33 | L126: =IF(J126="Forward charges", IF(I126="a",23.6, IF(I126="b",28.3, IF(I126="c",38.9, IF(I126="d",44.8, IF(I126="e",55.5,0))))), IF(I126="a",23.6, IF(I126="b",28.3, IF(I126="c",38.9, IF(I126="d",44.8, IF(I126="e",55.5,0)))))) -> 28.3 | M126: =K126 + ((E126*2 - 1) * L126) -> 117.9 | N126: =_xlfn.XLOOKUP('Final Report'!A126,Invoice!B:B,Invoice!H:H) -> 117.9 | O126: =N126-M126 -> 0

Sheet Summary
A2: Particular | B2: Count | C2: Amount(Rs)
A3: Total orders where X has been correctly charged | B3: =COUNTIF('Final Report'!O:O,0) -> 50 | C3: =SUMIF('Final Report'!O:O,0) -> 0
A4: Total Orders where X has been overcharged | B4: =COUNTIF('Final Report'!O:O,">0") -> 65 | C4: =SUMIF('Final Report'!O:O,">0") -> 4315.8
A5: Total Orders where X has been undercharged | B5: =COUNTIF('Final Report'!O:O,"<0") -> 9 | C5: =SUMIF('Final Report'!O:O,"<0") -> -312.4
A6: Total Orders | B6: =SUM(B3:B5) -> 124

Sheet Rates
A1: fwd_a_fixed | B1: fwd_a_additional | C1: fwd_b_fixed | D1: fwd_b_additional | E1: fwd_c_fixed | F1: fwd_c_additional | G1: fwd_d_fixed | H1: fwd_d_additional | I1: fwd_e_fixed | J1: fwd_e_additional | K1: rto_a_fixed | L1: rto_a_additional | M1: rto_b_fixed | N1: rto_b_additional | O1: rto_c_fixed | P1: rto_c_additional | Q1: rto_d_fixed | R1: rto_d_additional | S1: rto_e_fixed | T1: rto_e_additional
A2: 29.5 | B2: 23.6 | C2: 33 | D2: 28.3 | E2: 40.1 | F2: 38.9 | G2: 45.4 | H2: 44.8 | I2: 56.6 | J2: 55.5 | K2: 13.6 | L2: 23.6 | M2: 20.5 | N2: 28.3 | O2: 31.9 | P2: 38.9 | Q2: 41.3 | R2: 44.8 | S2: 50.7 | T2: 55.5

Sheet Pincode Zones
A1: Warehouse Pincode | B1: Customer Pincode | C1: Zone
A2: 121003 | B2: 507101 | C2: d
A3: 121003 | B3: 486886 | C3: d
A4: 121003 | B4: 532484 | C4: d
A5: 121003 | B5: 143001 | C5: b
A6: 121003 | B6: 515591 | C6: d
A7: 121003 | B7: 326502 | C7: d
A8: 121003 | B8: 208019 | C8: b
A9: 121003 | B9: 140301 | C9: b
A10: 121003 | B10: 396001 | C10: d
A11: 121003 | B11: 711106 | C11: d
A12: 121003 | B12: 284001 | C12: b
A13: 121003 | B13: 441601 | C13: d
... A125: 121003 | B125: 302020 | C125: b

Sheet Invoice
A1: AWB Code | B1: Order ID | C1: Charged Weight | D1: Warehouse Pincode | E1: Customer Pincode | F1: Zone | G1: Type of Shipment | H1: Billing Amount (Rs.)
A2: 1091117222124 | B2: 2001806232 | C2: 1.3 | D2: 121003 | E2: 507101 | F2: d | G2: Forward charges | H2: 135
A3: 1091117222194 | B3: 2001806273 | C3: 1 | D3: 121003 | E3: 486886 | F3: d | G3: Forward charges | H3: 90.2
A4: 1091117222931 | B4: 2001806408 | C4: 2.5 | D4: 121003 | E4: 532484 | F4: d | G4: Forward charges | H4: 224.6
A5: 1091117223244 | B5: 2001806458 | C5: 1 | D5: 121003 | E5: 143001 | F5: b | G5: Forward charges | H5: 61.3
A6: 1091117229345 | B6: 2001807012 | C6: 0.15 | D6: 121003 | E6: 515591 | F6: d | G6: Forward charges | H6: 45.4
A7: 1091117229555 | B7: 2001806686 | C7: 0.15 | D7: 121003 | E7: 326502 | F7: d | G7: Forward charges | H7: 45.4
A8: 1091117229776 | B8: 2001806885 | C8: 1 | D8: 121003 | E8: 208019 | F8: b | G8: Forward charges | H8: 61.3
A9: 1091117323112 | B9: 2001807058 | C9: 1.15 | D9: 121003 | E9: 140301 | F9: b | G9: Forward charges | H9: 89.6
A10: 1091117323812 | B10: 2001807186 | C10: 0.5 | D10: 121003 | E10: 396001 | F10: d | G10: Forward charges | H10: 45.4
A11: 1091117324206 | B11: 2001807290 | C11: 0.5 | D11: 121003 | E11: 711106 | F11: d | G11: Forward charges | H11: 45.4
A12: 1091117326612 | B12: 2001807814 | C12: 0.79 | D12: 121003 | E12: 284001 | F12: b | G12: Forward charges | H12: 61.3
A13: 1091117327172 | B13: 2001807931 | C13: 0.72 | D13: 121003 | E13: 441601 | F13: d | G13: Forward charges | H13: 90.2
... A125: 1091121846136 | B125: 2001811305 | C125: 0.5 | D125: 121003 | E125: 302020 | F125: d | G125: Forward charges | H125: 45.4

Sheet Order Report
A1: ExternOrderNo | B1: SKU | C1: Order Qty | D1: Column1 | E1: Total Weight | F1: Weight in kg | G1: Column2
A2: 2001827036 | B2: 8904223818706 | C2: 1 | D2: =VLOOKUP(Sheet1[[#This Row],[SKU]],'SKU Master'!$A:$B,2,FALSE) -> 127 | E2: =Sheet1[[#This Row],[Order Qty]]*Sheet1[[#This Row],[Column1]] -> 127 | F2: =Sheet1[[#This Row],[Total Weight]]/1000 -> 0.127 | G2: =CEILING(Sheet1[[#This Row],[Weight in kg]],0.5) -> 0.5
A3: 2001827036 | B3: 8904223819093 | C3: 1 | D3: =VLOOKUP(Sheet1[[#This Row],[SKU]],'SKU Master'!$A:$B,2,FALSE) -> 150 | E3: =Sheet1[[#This Row],[Order Qty]]*Sheet1[[#This Row],[Column1]] -> 150 | F3: =Sheet1[[#This Row],[Total Weight]]/1000 -> 0.15 | G3: =CEILING(Sheet1[[#This Row],[Weight in kg]],0.5) -> 0.5
A4: 2001827036 | B4: 8904223819109 | C4: 1 | D4: =VLOOKUP(Sheet1[[#This Row],[SKU]],'SKU Master'!$A:$B,2,FALSE) -> 100 | E4: =Sheet1[[#This Row],[Order Qty]]*Sheet1[[#This Row],[Column1]] -> 100 | F4: =Sheet1[[#This Row],[Total Weight]]/1000 -> 0.1 | G4: =CEILING(Sheet1[[#This Row],[Weight in kg]],0.5) -> 0.5
A5: 2001827036 | B5: 8904223818430 | C5: 1 | D5: =VLOOKUP(Sheet1[[#This Row],[SKU]],'SKU Master'!$A:$B,2,FALSE) -> 165 | E5: =Sheet1[[#This Row],[Order Qty]]*Sheet1[[#This Row],[Column1]] -> 165 | F5: =Sheet1[[#This Row],[Total Weight]]/1000 -> 0.165 | G5: =CEILING(Sheet1[[#This Row],[Weight in kg]],0.5) -> 0.5
A6: 2001827036 | B6: 8904223819277 | C6: 1 | D6: =VLOOKUP(Sheet1[[#This Row],[SKU]],'SKU Master'!$A:$B,2,FALSE) -> 350 | E6: =Sheet1[[#This Row],[Order Qty]]*Sheet1[[#This Row],[Column1]] -> 350 | F6: =Sheet1[[#This Row],[Total Weight]]/1000 -> 0.35 | G6: =CEILING(Sheet1[[#This Row],[Weight in kg]],0.5) -> 0.5
A7: 2001827036 | B7: GIFTBOX202002 | C7: 1 | D7: =VLOOKUP(Sheet1[[#This Row],[SKU]],'SKU Master'!$A:$B,2,FALSE) -> 500 | E7: =Sheet1[[#This Row],[Order Qty]]*Sheet1[[#This Row],[Column1]] -> 500 | F7: =Sheet1[[#This Row],[Total Weight]]/1000 -> 0.5 | G7: =CEILING(Sheet1[[#This Row],[Weight in kg]],0.5) -> 0.5
A8: 2001827036 | B8: 8904223818638 | C8: 2 | D8: =VLOOKUP(Sheet1[[#This Row],[SKU]],'SKU Master'!$A:$B,2,FALSE) -> 137 | E8: =Sheet1[[#This Row],[Order Qty]]*Sheet1[[#This Row],[Column1]] -> 274 | F8: =Sheet1[[#This Row],[Total Weight]]/1000 -> 0.274 | G8: =CEILING(Sheet1[[#This Row],[Weight in kg]],0.5) -> 0.5
A9: 2001827036 | B9: SACHETS001 | C9: 1 | D9: =VLOOKUP(Sheet1[[#This Row],[SKU]],'SKU Master'!$A:$B,2,FALSE) -> 10 | E9: =Sheet1[[#This Row],[Order Qty]]*Sheet1[[#This Row],[Column1]] -> 10 | F9: =Sheet1[[#This Row],[Total Weight]]/1000 -> 0.01 | G9: =CEILING(Sheet1[[#This Row],[Weight in kg]],0.5) -> 0.5
A10: 2001825261 | B10: 8904223819024 | C10: 4 | D10: =VLOOKUP(Sheet1[[#This Row],[SKU]],'SKU Master'!$A:$B,2,FALSE) -> 112 | E10: =Sheet1[[#This Row],[Order Qty]]*Sheet1[[#This Row],[Column1]] -> 448 | F10: =Sheet1[[#This Row],[Total Weight]]/1000 -> 0.448 | G10: =CEILING(Sheet1[[#This Row],[Weight in kg]],0.5) -> 0.5
A11: 2001825261 | B11: 8904223819291 | C11: 4 | D11: =VLOOKUP(Sheet1[[#This Row],[SKU]],'SKU Master'!$A:$B,2,FALSE) -> 112 | E11: =Sheet1[[#This Row],[Order Qty]]*Sheet1[[#This Row],[Column1]] -> 448 | F11: =Sheet1[[#This Row],[Total Weight]]/1000 -> 0.448 | G11: =CEILING(Sheet1[[#This Row],[Weight in kg]],0.5) -> 0.5
A12: 2001825261 | B12: 8904223818638 | C12: 3 | D12: =VLOOKUP(Sheet1[[#This Row],[SKU]],'SKU Master'!$A:$B,2,FALSE) -> 137 | E12: =Sheet1[[#This Row],[Order Qty]]*Sheet1[[#This Row],[Column1]] -> 411 | F12: =Sheet1[[#This Row],[Total Weight]]/1000 -> 0.411 | G12: =CEILING(Sheet1[[#This Row],[Weight in kg]],0.5) -> 0.5
A13: 2001825261 | B13: 8904223818669 | C13: 1 | D13: =VLOOKUP(Sheet1[[#This Row],[SKU]],'SKU Master'!$A:$B,2,FALSE) -> 240 | E13: =Sheet1[[#This Row],[Order Qty]]*Sheet1[[#This Row],[Column1]] -> 240 | F13: =Sheet1[[#This Row],[Total Weight]]/1000 -> 0.24 | G13: =CEILING(Sheet1[[#This Row],[Weight in kg]],0.5) -> 0.5
A14: 2001825261 | B14: SACHETS001 | C14: 1 | D14: =VLOOKUP(Sheet1[[#This Row],[SKU]],'SKU Master'!$A:$B,2,FALSE) -> 10 | E14: =Sheet1[[#This Row],[Order Qty]]*Sheet1[[#This Row],[Column1]] -> 10 | F14: =Sheet1[[#This Row],[Total Weight]]/1000 -> 0.01 | G14: =CEILING(Sheet1[[#This Row],[Weight in kg]],0.5) -> 0.5
A15: 2001823564 | B15: 8904223819291 | C15: 2 | D15: =VLOOKUP(Sheet1[[#This Row],[SKU]],'SKU Master'!$A:$B,2,FALSE) -> 112 | E15: =Sheet1[[#This Row],[Order Qty]]*Sheet1[[#This Row],[Column1]] -> 224 | F15: =Sheet1[[#This Row],[Total Weight]]/1000 -> 0.224 | G15: =CEILING(Sheet1[[#This Row],[Weight in kg]],0.5) -> 0.5
A16: 2001823564 | B16: 8904223819031 | C16: 2 | D16: =VLOOKUP(Sheet1[[#This Row],[SKU]],'SKU Master'!$A:$B,2,FALSE) -> 112 | E16: =Sheet1[[#This Row],[Order Qty]]*Sheet1[[#This Row],[Column1]] -> 224 | F16: =Sheet1[[#This Row],[Total Weight]]/1000 -> 0.224 | G16: =CEILING(Sheet1[[#This Row],[Weight in kg]],0.5) -> 0.5
A17: 2001823564 | B17: 8904223819024 | C17: 2 | D17: =VLOOKUP(Sheet1[[#This Row],[SKU]],'SKU Master'!$A:$B,2,FALSE) -> 112 | E17: =Sheet1[[#This Row],[Order Qty]]*Sheet1[[#This Row],[Column1]] -> 224 | F17: =Sheet1[[#This Row],[Total Weight]]/1000 -> 0.224 | G17: =CEILING(Sheet1[[#This Row],[Weight in kg]],0.5) -> 0.5
A18: 2001822466 | B18: 8904223819468 | C18: 2 | D18: =VLOOKUP(Sheet1[[#This Row],[SKU]],'SKU Master'!$A:$B,2,FALSE) -> 240 | E18: =Sheet1[[#This Row],[Order Qty]]*Sheet1[[#This Row],[Column1]] -> 480 | F18: =Sheet1[[#This Row],[Total Weight]]/1000 -> 0.48 | G18: =CEILING(Sheet1[[#This Row],[Weight in kg]],0.5) -> 0.5
A19: 2001822466 | B19: 8904223819291 | C19: 8 | D19: =VLOOKUP(Sheet1[[#This Row],[SKU]],'SKU Master'!$A:$B,2,FALSE) -> 112 | E19: =Sheet1[[#This Row],[Order Qty]]*Sheet1[[#This Row],[Column1]] -> 896 | F19: =Sheet1[[#This Row],[Total Weight]]/1000 -> 0.896 | G19: =CEILING(Sheet1[[#This Row],[Weight in kg]],0.5) -> 1
A20: 2001821995 | B20: 8904223819130 | C20: 1 | D20: =VLOOKUP(Sheet1[[#This Row],[SKU]],'SKU Master'!$A:$B,2,FALSE) -> 350 | E20: =Sheet1[[#This Row],[Order Qty]]*Sheet1[[#This Row],[Column1]] -> 350 | F20: =Sheet1[[#This Row],[Total Weight]]/1000 -> 0.35 | G20: =CEILING(Sheet1[[#This Row],[Weight in kg]],0.5) -> 0.5
A21: 2001821995 | B21: 8904223818706 | C21: 1 | D21: =VLOOKUP(Sheet1[[#This Row],[SKU]],'SKU Master'!$A:$B,2,FALSE) -> 127 | E21: =Sheet1[[#This Row],[Order Qty]]*Sheet1[[#This Row],[Column1]] -> 127 | F21: =Sheet1[[#This Row],[Total Weight]]/1000 -> 0.127 | G21: =CEILING(Sheet1[[#This Row],[Weight in kg]],0.5) -> 0.5
A22: 2001821766 | B22: 8904223818591 | C22: 2 | D22: =VLOOKUP(Sheet1[[#This Row],[SKU]],'SKU Master'!$A:$B,2,FALSE) -> 120 | E22: =Sheet1[[#This Row],[Order Qty]]*Sheet1[[#This Row],[Column1]] -> 240 | F22: =Sheet1[[#This Row],[Total Weight]]/1000 -> 0.24 | G22: =CEILING(Sheet1[[#This Row],[Weight in kg]],0.5) -> 0.5
A23: 2001821750 | B23: 8904223818850 | C23: 1 | D23: =VLOOKUP(Sheet1[[#This Row],[SKU]],'SKU Master'!$A:$B,2,FALSE) -> 240 | E23: =Sheet1[[#This Row],[Order Qty]]*Sheet1[[#This Row],[Column1]] -> 240 | F23: =Sheet1[[#This Row],[Total Weight]]/1000 -> 0.24 | G23: =CEILING(Sheet1[[#This Row],[Weight in kg]],0.5) -> 0.5
A24: 2001821750 | B24: 8904223818430 | C24: 1 | D24: =VLOOKUP(Sheet1[[#This Row],[SKU]],'SKU Master'!$A:$B,2,FALSE) -> 165 | E24: =Sheet1[[#This Row],[Order Qty]]*Sheet1[[#This Row],[Column1]] -> 165 | F24: =Sheet1[[#This Row],[Total Weight]]/1000 -> 0.165 | G24: =CEILING(Sheet1[[#This Row],[Weight in kg]],0.5) -> 0.5
A25: 2001821750 | B25: 8904223819130 | C25: 1 | D25: =VLOOKUP(Sheet1[[#This Row],[SKU]],'SKU Master'!$A:$B,2,FALSE) -> 350 | E25: =Sheet1[[#This Row],[Order Qty]]*Sheet1[[#This Row],[Column1]] -> 350 | F25: =Sheet1[[#This Row],[Total Weight]]/1000 -> 0.35 | G25: =CEILING(Sheet1[[#This Row],[Weight in kg]],0.5) -> 0.5
A26: 2001821742 | B26: 8904223819468 | C26: 1 | D26: =VLOOKUP(Sheet1[[#This Row],[SKU]],'SKU Master'!$A:$B,2,FALSE) -> 240 | E26: =Sheet1[[#This Row],[Order Qty]]*Sheet1[[#This Row],[Column1]] -> 240 | F26: =Sheet1[[#This Row],[Total Weight]]/1000 -> 0.24 | G26: =CEILING(Sheet1[[#This Row],[Weight in kg]],0.5) -> 0.5
... A47: 2001819252 | B47: 8904223818706 | C47: 1 | D47: =VLOOKUP(Sheet1[[#This Row],[SKU]],'SKU Master'!$A:$B,2,FALSE) -> 127 | E47: =Sheet1[[#This Row],[Order Qty]]*Sheet1[[#This Row],[Column1]] -> 127 | F47: =Sheet1[[#This Row],[Total Weight]]/1000 -> 0.127 | G47: =CEILING(Sheet1[[#This Row],[Weight in kg]],0.5) -> 0.5
A48: 2001819252 | B48: SACHETS001 | C48: 1 | D48: =VLOOKUP(Sheet1[[#This Row],[SKU]],'SKU Master'!$A:$B,2,FALSE) -> 10 | E48: =Sheet1[[#This Row],[Order Qty]]*Sheet1[[#This Row],[Column1]] -> 10 | F48: =Sheet1[[#This Row],[Total Weight]]/1000 -> 0.01 | G48: =CEILING(Sheet1[[#This Row],[Weight in kg]],0.5) -> 0.5
A49: 2001818390 | B49: 8904223819147 | C49: 1 | D49: =VLOOKUP(Sheet1[[#This Row],[SKU]],'SKU Master'!$A:$B,2,FALSE) -> 240 | E49: =Sheet1[[#This Row],[Order Qty]]*Sheet1[[#This Row],[Column1]] -> 240 | F49: =Sheet1[[#This Row],[Total Weight]]/1000 -> 0.24 | G49: =CEILING(Sheet1[[#This Row],[Weight in kg]],0.5) -> 0.5
A50: 2001818390 | B50: 8904223818935 | C50: 4 | D50: =VLOOKUP(Sheet1[[#This Row],[SKU]],'SKU Master'!$A:$B,2,FALSE) -> 120 | E50: =Sheet1[[#This Row],[Order Qty]]*Sheet1[[#This Row],[Column1]] -> 480 | F50: =Sheet1[[#This Row],[Total Weight]]/1000 -> 0.48 | G50: =CEILING(Sheet1[[#This Row],[Weight in kg]],0.5) -> 0.5
A51: 2001818390 | B51: 8904223818683 | C51: 1 | D51: =VLOOKUP(Sheet1[[#This Row],[SKU]],'SKU Master'!$A:$B,2,FALSE) -> 121 | E51: =Sheet1[[#This Row],[Order Qty]]*Sheet1[[#This Row],[Column1]] -> 121 | F51: =Sheet1[[#This Row],[Total Weight]]/1000 -> 0.121 | G51: =CEILING(Sheet1[[#This Row],[Weight in kg]],0.5) -> 0.5
A52: 2001817160 | B52: 8904223818478 | C52: 1 | D52: =VLOOKUP(Sheet1[[#This Row],[SKU]],'SKU Master'!$A:$B,2,FALSE) -> 350 | E52: =Sheet1[[#This Row],[Order Qty]]*Sheet1[[#This Row],[Column1]] -> 350 | F52: =Sheet1[[#This Row],[Total Weight]]/1000 -> 0.35 | G52: =CEILING(Sheet1[[#This Row],[Weight in kg]],0.5) -> 0.5
A53: 2001817160 | B53: 8904223819284 | C53: 1 | D53: =VLOOKUP(Sheet1[[#This Row],[SKU]],'SKU Master'!$A:$B,2,FALSE) -> 350 | E53: =Sheet1[[#This Row],[Order Qty]]*Sheet1[[#This Row],[Column1]] -> 350 | F53: =Sheet1[[#This Row],[Total Weight]]/1000 -> 0.35 | G53: =CEILING(Sheet1[[#This Row],[Weight in kg]],0.5) -> 0.5
A54: 2001817093 | B54: 8904223816214 | C54: 1 | D54: =VLOOKUP(Sheet1[[#This Row],[SKU]],'SKU Master'!$A:$B,2,FALSE) -> 120 | E54: =Sheet1[[#This Row],[Order Qty]]*Sheet1[[#This Row],[Column1]] -> 120 | F54: =Sheet1[[#This Row],[Total Weight]]/1000 -> 0.12 | G54: =CEILING(Sheet1[[#This Row],[Weight in kg]],0.5) -> 0.5
A55: 2001817093 | B55: 8904223818874 | C55: 1 | D55: =VLOOKUP(Sheet1[[#This Row],[SKU]],'SKU Master'!$A:$B,2,FALSE) -> 100 | E55: =Sheet1[[#This Row],[Order Qty]]*Sheet1[[#This Row],[Column1]] -> 100 | F55: =Sheet1[[#This Row],[Total Weight]]/1000 -> 0.1 | G55: =CEILING(Sheet1[[#This Row],[Weight in kg]],0.5) -> 0.5
A56: 2001817093 | B56: 8904223819512 | C56: 1 | D56: =VLOOKUP(Sheet1[[#This Row],[SKU]],'SKU Master'!$A:$B,2,FALSE) -> 210 | E56: =Sheet1[[#This Row],[Order Qty]]*Sheet1[[#This Row],[Column1]] -> 210 | F56: =Sheet1[[#This Row],[Total Weight]]/1000 -> 0.21 | G56: =CEILING(Sheet1[[#This Row],[Weight in kg]],0.5) -> 0.5
A57: 2001817093 | B57: 8904223818881 | C57: 1 | D57: =VLOOKUP(Sheet1[[#This Row],[SKU]],'SKU Master'!$A:$B,2,FALSE) -> 140 | E57: =Sheet1[[#This Row],[Order Qty]]*Sheet1[[#This Row],[Column1]] -> 140 | F57: =Sheet1[[#This Row],[Total Weight]]/1000 -> 0.14 | G57: =CEILING(Sheet1[[#This Row],[Weight in kg]],0.5) -> 0.5
A58: 2001817093 | B58: 8904223819291 | C58: 2 | D58: =VLOOKUP(Sheet1[[#This Row],[SKU]],'SKU Master'!$A:$B,2,FALSE) -> 112 | E58: =Sheet1[[#This Row],[Order Qty]]*Sheet1[[#This Row],[Column1]] -> 224 | F58: =Sheet1[[#This Row],[Total Weight]]/1000 -> 0.224 | G58: =CEILING(Sheet1[[#This Row],[Weight in kg]],0.5) -> 0.5
A59: 2001817093 | B59: 8904223819031 | C59: 2 | D59: =VLOOKUP(Sheet1[[#This Row],[SKU]],'SKU Master'!$A:$B,2,FALSE) -> 112 | E59: =Sheet1[[#This Row],[Order Qty]]*Sheet1[[#This Row],[Column1]] -> 224 | F59: =Sheet1[[#This Row],[Total Weight]]/1000 -> 0.224 | G59: =CEILING(Sheet1[[#This Row],[Weight in kg]],0.5) -> 0.5
A60: 2001817093 | B60: 8904223819024 | C60: 2 | D60: =VLOOKUP(Sheet1[[#This Row],[SKU]],'SKU Master'!$A:$B,2,FALSE) -> 112 | E60: =Sheet1[[#This Row],[Order Qty]]*Sheet1[[#This Row],[Column1]] -> 224 | F60: =Sheet1[[#This Row],[Total Weight]]/1000 -> 0.224 | G60: =CEILING(Sheet1[[#This Row],[Weight in kg]],0.5) -> 0.5
...

Sheet SKU Master
A1: SKU | B1: Weight (g)
A2: 8904223815682 | B2: 210
A3: 8904223815859 | B3: 165
A4: 8904223815866 | B4: 113
A5: 8904223815873 | B5: 65
A6: 8904223816214 | B6: 120
A7: 8904223816665 | B7: 102
A8: 8904223817273 | B8: 65
A9: 8904223817334 | B9: 170
A10: 8904223817501 | B10: 350
A11: 8904223818430 | B11: 165
A12: 8904223818478 | B12: 350
A13: 8904223818553 | B13: 115
... A51: 8904223819437 | B51: 552
A52: GIFTBOX202001 | B52: 500
A53: GIFTBOX202004 | B53: 500
A54: GIFTBOX202002 | B54: 500
A55: 8904223819369 | B55: 170
A56: GIFTBOX202003 | B56: 500
A57: 8904223819123 | B57: 250
A58: GIFTBOX202002 | B58: 500
A59: 8904223819468 | B59: 240
A60: 8904223819260 | B60: 130
A61: 8904223819321 | B61: 600
A62: 8904223819338 | B62: 600
A63: 8904223819505 | B63: 210
A64: 8904223819499 | B64: 210
A65: 8904223819512 | B65: 210
A66: 8904223819543 | B66: 300
A67: SACHETS001 | B67: 10

Sheet Pivot Table
A2: Total Weight Per Order
A3: Row Labels | B3: Sum of Total Weight | C3: ZONE
A4: 2001806210 | B4: 220 | C4: =_xlfn.XLOOKUP(A4,Invoice!B:B,Invoice!F:F) -> b
A5: 2001806226 | B5: 480 | C5: =_xlfn.XLOOKUP(A5,Invoice!B:B,Invoice!F:F) -> d
A6: 2001806229 | B6: 500 | C6: =_xlfn.XLOOKUP(A6,Invoice!B:B,Invoice!F:F) -> d
A7: 2001806232 | B7: 1302 | C7: =_xlfn.XLOOKUP(A7,Invoice!B:B,Invoice!F:F) -> d
A8: 2001806233 | B8: 245 | C8: =_xlfn.XLOOKUP(A8,Invoice!B:B,Invoice!F:F) -> b
A9: 2001806251 | B9: 245 | C9: =_xlfn.XLOOKUP(A9,Invoice!B:B,Invoice!F:F) -> d
A10: 2001806273 | B10: 615 | C10: =_xlfn.XLOOKUP(A10,Invoice!B:B,Invoice!F:F) -> d
A11: 2001806304 | B11: 500 | C11: =_xlfn.XLOOKUP(A11,Invoice!B:B,Invoice!F:F) -> d
A12: 2001806338 | B12: 500 | C12: =_xlfn.XLOOKUP(A12,Invoice!B:B,Invoice!F:F) -> d
A13: 2001806408 | B13: 2265 | C13: =_xlfn.XLOOKUP(A13,Invoice!B:B,Invoice!F:F) -> d
A14: 2001806446 | B14: 500 | C14: =_xlfn.XLOOKUP(A14,Invoice!B:B,Invoice!F:F) -> d
A15: 2001806458 | B15: 700 | C15: =_xlfn.XLOOKUP(A15,Invoice!B:B,Invoice!F:F) -> b
... A127: 2001827036 | B127: 1676 | C127: =_xlfn.XLOOKUP(A127,Invoice!B:B,Invoice!F:F) -> b
A128: Grand Total | B128: 87976
